2020-05-14T17:28:10.032629+00:00 app[worker.1]:   File "/usr/lib/python3.8/asyncio/base_events.py", line 616, in run_until_complete
2020-05-14T17:28:10.032629+00:00 app[worker.1]:     return future.result()
2020-05-14T17:28:10.032630+00:00 app[worker.1]:   File "/usr/lib/python3.8/site-packages/telethon/client/auth.py", line 636, in __aenter__
2020-05-14T17:28:10.032630+00:00 app[worker.1]:     return await self.start()
2020-05-14T17:28:10.032630+00:00 app[worker.1]:   File "/usr/lib/python3.8/site-packages/telethon/client/auth.py", line 139, in _start
2020-05-14T17:28:10.032631+00:00 app[worker.1]:     await self.connect()
2020-05-14T17:28:10.032632+00:00 app[worker.1]:   File "/usr/lib/python3.8/site-packages/telethon/client/telegrambaseclient.py", line 486, in connect
2020-05-14T17:28:10.032632+00:00 app[worker.1]:     await self._sender.send(self._init_with(
2020-05-14T17:28:10.032633+00:00 app[worker.1]: telethon.errors.rpcerrorlist.AuthKeyDuplicatedError: The authorization key (session file) was used under two different IP addresses simultaneously, and can no longer be used. Use the same session exclusively, or use different sessions (caused by InvokeWithLayerRequest)
2020-05-14T17:28:10.351243+00:00 heroku[worker.1]: State changed from up to crashed